Workbook

Sheet Read Me
B2: RED STRINGS LAB · CASE 07 · Fix the Messy Dataset — Starter Sheet
B3: Every dataset is hiding something.
B5: ⚠ ALL data here is MADE UP, and deliberately messy. 'Town High' is imaginary.
B6: This is a morning-routine survey. Real survey exports look like this: typos, doubles, mixed units.
B8: THE QUESTION: Before analysing anything, can we trust this file?
B10: TABS
B11: • Messy — the raw file (108 rows). This is what you clean.
B12: • Clean — the same survey after cleaning with the rules in the Cleaning Log (100 students). Check your work against it.
B13: • Cleaning Log — every kind of problem found, how many, what was done, and why.
B14: • Compare — messy vs clean labels, charts, and what the same formulas say on each.
B15: • Your Turn — your own cleaning log. • Answer Key — the numbers behind the video.
B17: MISSION
... B23: Not affiliated with Google or any tool shown. Free to use for learning. Terms checked: [add date].

Sheet Messy
A1: Response ID | B1: Year group | C1: Height | D1: Sleep (hours) | E1: Breakfast? | F1: Travel to school | H1: Made-up, deliberately messy data. Blue = typed-in inputs.
A2: 89 | B2: Year 12 | C2: 162 | D2: 7.5 | E2: Yes | F2: Walking
A3: 55 | B3: Yr 12 | C3: 157 | D3: 7 | E3: No | F3: Walk
A4: 57 | B4: 10 | C4: 166 cm | D4: 7 | E4: Yes | F4: Buss
A5: 2 | B5: Year 12 | C5: 171 | D5: 7 | E5: No | F5: Bus
A6: 88 | B6: Year 10 | C6: 168 | D6: 6.5 | E6: Yes | F6: Car
A7: 80 | B7: Year 12 | C7: 169 | D7: 7 | E7: Yes | F7: Buss
A8: 36 | B8: Year 9 | C8: 180 | D8: 7 | E8: Yes | F8: Bike
A9: 68 | B9: Yr 9 | C9: 178 | D9: 8h | E9: Y | F9: Bus
A10: 74 | B10: 12 | C10: 1.58 | D10: 5.5 | E10: Yes | F10: Car
A11: 22 | B11: Year 12 | C11: 166 | D11: 6 | E11: Yes | F11: Bus
A12: 74 | B12: 12 | C12: 1.58 | D12: 5.5 | E12: Yes | F12: Car
A13: 100 | B13: Yr 10 | C13: 155 | D13: 7.5 | E13: Yes | F13: Car
A14: 87 | B14: 11 | C14: 176 | D14: 7.5 | E14: Yes | F14: Buss
A15: 20 | B15: Year 12 | C15: 1.71 | D15: 5.5 | E15: Yes | F15: Car
A16: 10 | B16: Year 10 | C16: 170 | D16: 7 hours | E16: No | F16: Car
A17: 72 | B17: Year 10 | C17: 171 | D17: 7.5 | E17: Yess | F17: Car
A18: 83 | B18: 11 | C18: 170 | D18: 7.5 | E18: N | F18: Walk
A19: 86 | B19: 9 | C19: 172 | D19: 7 | E19: Yes | F19: Buss
A20: 24 | B20: Year 11 | C20: 1650 | D20: 7.5 | E20: No | F20: School bus
A21: 5 | B21: Yr 12 | C21: 184 | D21: 8.5 | E21: Yes | F21: Buss
A22: 82 | B22: Year 9 | C22: 170 | D22: 7 | E22: No | F22: Walking
A23: 48 | B23: Year 9 | C23: 166 | D23: 7.5 | E23: N | F23: Walk
A24: 64 | B24: Year 9 | C24: 1.6 | D24: 7 | E24: Yes | F24: Buss
A25: 27 | B25: Year 12 | C25: 177 | D25: 9 | E25: No | F25: Car
A26: 42 | B26: 10 | C26: 174 | D26: 7 | E26: Yes | F26: School bus
A27: 17 | B27: Year 12 | C27: 172 | D27: 7.5 | E27: No | F27: Bus
A28: 30 | B28: Year 12 | C28: 165 | D28: 7.5 | E28: Y | F28: Buss
... A39: 35 | B39: Year 9 | C39: 1690 | D39: 7 | E39: Yess | F39: Car
A40: 1 | B40: Yr 9 | C40: 168 | D40: 8h | E40: Yess | F40: Walk
A41: 65 | B41: Yr 11 | C41: 175 | D41: 7 | E41: No | F41: Car
A42: 19 | B42: 9 | C42: 172 | D42: 5.5 | E42: Yes | F42: Cycle
A43: 52 | B43: Yr 12 | C43: 191 | D43: 6.5 | E43: Yes | F43: Walk
A44: 13 | B44: Year 10 | C44: 168 cm | D44: 6.5 | E44: Yes | F44: Buss
A45: 21 | B45: Yr 11 | C45: 168 | D45: 5 | E45: Yess | F45: Bus
A46: 15 | B46: 9 | C46: 1.63 m | D46: 6 | E46: Yes | F46: Bus
A47: 39 | B47: Yr 9 | C47: 160 | D47: 8 | E47: No | F47: Car
A48: 16 | B48: 9 | C48: 179 | D48: 7 | E48: No | F48: Car
A49: 75 | B49: Year 10 | C49: 167 | D49: 8.5 | E49: No | F49: Bike
A50: 63 | B50: Year 10 | C50: 156 | D50: 7.5 | E50: No | F50: Bus
...

Sheet Clean
A1: Response ID | B1: Year group | C1: Height (cm) | D1: Sleep (hours) | E1: Breakfast? | F1: Travel to school | H1: Cleaned by the Cleaning Log rules. Blank = could not be recovered safely.
A2: 1 | B2: 9 | C2: 168 | D2: 8 | E2: Yes | F2: Walk
A3: 2 | B3: 12 | C3: 171 | D3: 7 | E3: No | F3: Bus
A4: 3 | B4: 11 | C4: 174 | D4: 7 | E4: Yes | F4: Walk
A5: 4 | B5: 11 | C5: 174 | D5: 7 | E5: Yes | F5: Bus
A6: 5 | B6: 12 | C6: 184 | D6: 8.5 | E6: Yes | F6: Bus
A7: 6 | B7: 9 | C7: 167 | D7: 8 | E7: No | F7: Car
A8: 7 | B8: 12 | C8: 166 | D8: 8.5 | E8: Yes | F8: Bus
A9: 8 | B9: 10 | C9: 159 | D9: 7 | E9: Yes | F9: Bike
A10: 9 | B10: 12 | C10: 170 | D10: 6 | E10: Yes | F10: Bus
A11: 10 | B11: 10 | C11: 170 | D11: 7 | E11: No | F11: Car
A12: 11 | B12: 10 | C12: 161 | D12: 8.5 | E12: Yes | F12: Bus
A13: 12 | B13: 10 | C13: 168 | D13: 8.5 | E13: No | F13: Bus
... A24: 23 | B24: 11 | C24: 165 | D24: 5 | E24: No | F24: Bike
A25: 24 | B25: 11 | D25: 7.5 | E25: No | F25: Bus
A26: 25 | B26: 12 | C26: 171 | D26: 6 | E26: Yes | F26: Walk
A27: 26 | B27: 9 | C27: 167 | D27: 6.5 | E27: Yes | F27: Car
A28: 27 | B28: 12 | C28: 177 | D28: 9 | E28: No | F28: Car
A29: 28 | B29: 10 | C29: 180 | D29: 7.5 | E29: Yes | F29: Bus
A30: 29 | B30: 11 | C30: 168 | D30: 6.5 | E30: No | F30: Car
A31: 30 | B31: 12 | C31: 165 | D31: 7.5 | E31: Yes | F31: Bus
A32: 31 | B32: 10 | C32: 180 | D32: 8 | E32: Yes | F32: Car
A33: 32 | B33: 12 | C33: 167 | D33: 8.5 | E33: Yes | F33: Car
A34: 33 | B34: 9 | C34: 170 | D34: 6.5 | E34: Yes | F34: Car
A35: 34 | B35: 11 | C35: 165 | D35: 7.5 | E35: Yes | F35: Walk
A36: 35 | B36: 9 | D36: 7 | E36: Yes | F36: Car
A37: 36 | B37: 9 | C37: 180 | D37: 7 | E37: Yes | F37: Bike
A38: 37 | B38: 9 | C38: 176 | D38: 6.5 | E38: Yes | F38: Walk
A39: 38 | B39: 12 | C39: 158 | D39: 8 | E39: Yes | F39: Bus
A40: 39 | B40: 9 | C40: 160 | D40: 8 | E40: No | F40: Car
A41: 40 | B41: 9 | C41: 164 | D41: 5.5 | E41: Yes | F41: Walk
A42: 41 | B42: 10 | C42: 165 | D42: 6.5 | E42: Yes | F42: Bus
A43: 42 | B43: 10 | C43: 174 | D43: 7 | E43: Yes | F43: Bus
A44: 43 | B44: 10 | C44: 149 | D44: 8 | E44: No | F44: Bus
A45: 44 | B45: 10 | C45: 180 | D45: 7.5 | E45: No | F45: Bus
A46: 45 | B46: 10 | C46: 158 | D46: 8 | E46: Yes | F46: Bus
A47: 46 | B47: 10 | C47: 177 | D47: 7 | E47: Yes | F47: Car
A48: 47 | B48: 11 | C48: 157 | D48: 6.5 | E48: Yes | F48: Bus
... A54: 53 | B54: 10 | C54: 163 | D54: 7 | E54: No | F54: Walk
A55: 54 | B55: 9 | D55: 8 | E55: No | F55: Bus
...

Sheet Cleaning Log
A1: Problem | B1: Example | C1: Rows affected | D1: What I did | E1: Why
A2: Duplicate submissions | B2: Same Response ID twice | C2: =COUNTA(Messy!A2:A109)-COUNTA(Clean!A2:A101) -> 8 | D2: Kept one copy of each | E2: Counting a student twice distorts every average and percentage
A3: Height in metres | B3: 1.65 | C3: 14 | D3: Multiplied by 100 to get cm | E3: Mixed units make an average meaningless
A4: Height as text with units | B4: 165 cm | C4: 4 | D4: Removed ' cm', stored as a number | E4: AVERAGE ignores text silently
A5: Height as text in metres | B5: 1.65 m | C5: 3 | D5: Converted to cm | E5: Same reason
A6: Impossible height (typo) | B6: 1650 | C6: 2 | D6: Left BLANK and logged | E6: Could be 165 or 1.65 or something else. Guessing would be invention
A7: Height not given | B7: n/a | C7: 1 | D7: Left BLANK | E7: Missing is honest
A8: Sleep as text | B8: 7 hours / 8h | C8: 4 | D8: Kept the number | E8: Text is skipped by AVERAGE
A9: Impossible sleep | B9: 25 | C9: 1 | D9: Left BLANK and logged | E9: More than a day. Can't know the real value
A10: Year group written many ways | B10: Yr 9 / 9 / Year 9 (trailing space) | C10: all rows | D10: Made it the number 9, 10, 11 or 12 | E10: One label per group
A11: Breakfast written many ways | B11: Y / Yes (space) / Yess / N | C11: all rows | D11: Made it Yes or No | E11: COUNTIF('Yes') misses the variants
A12: Travel written many ways | B12: Buss / Walking / School bus / Cycle | C12: all rows | D12: Made it Bus, Walk, Car or Bike | E12: 11 labels for 4 ideas

Sheet Compare
A1: TRAVEL TO SCHOOL: messy labels vs clean labels
A2: Messy label | B2: Count | D2: Clean label | E2: Count
A3: Bus | B3: =COUNTIF(Messy!$F$2:$F$109,A3) -> 19 | D3: Bus | E3: =COUNTIF(Clean!$F$2:$F$101,D3) -> 44
A4: Buss | B4: =COUNTIF(Messy!$F$2:$F$109,A4) -> 14 | D4: Walk | E4: =COUNTIF(Clean!$F$2:$F$101,D4) -> 23
A5: Bus | B5: =COUNTIF(Messy!$F$2:$F$109,A5) -> 10 | D5: Car | E5: =COUNTIF(Clean!$F$2:$F$101,D5) -> 25
A6: School bus | B6: =COUNTIF(Messy!$F$2:$F$109,A6) -> 6 | D6: Bike | E6: =COUNTIF(Clean!$F$2:$F$101,D6) -> 8
A7: Walk | B7: =COUNTIF(Messy!$F$2:$F$109,A7) -> 12
A8: Walking | B8: =COUNTIF(Messy!$F$2:$F$109,A8) -> 3
A9: Walk | B9: =COUNTIF(Messy!$F$2:$F$109,A9) -> 9
A10: Car | B10: =COUNTIF(Messy!$F$2:$F$109,A10) -> 22
A11: Car | B11: =COUNTIF(Messy!$F$2:$F$109,A11) -> 5
A12: Bike | B12: =COUNTIF(Messy!$F$2:$F$109,A12) -> 5
A13: Cycle | B13: =COUNTIF(Messy!$F$2:$F$109,A13) -> 3
A15: Total rows counted | B15: =SUM(B3:B13) -> 108 | D15: Total students | E15: =SUM(E3:E6) -> 100

Sheet Your Turn
A1: What was wrong | B1: Example | C1: How many rows | D1: What I did | E1: Why I did it that way (or why I left it blank)
A2: EXAMPLE: height in metres | B2: 1.65 | C2: 14 | D2: Multiplied by 100 | E2: So every height is in cm
A14: Yellow = yours to fill. Delete the grey example row. Keep the original data untouched.

Sheet Answer Key
A1: ANSWER KEY (made-up data) — try it yourself first
A3: Same question, same formula | B3: On MESSY | C3: On CLEAN | D3: What it tells you
A4: Rows / students counted | B4: =COUNTA(Messy!A2:A109) -> 108 | C4: =COUNTA(Clean!A2:A101) -> 100 | D4: 8 students were counted twice
A5: Heights stored as text (invisible to AVERAGE) | B5: =COUNTA(Messy!C2:C109)-COUNT(Messy!C2:C109) -> 10 | C5: =COUNTA(Clean!C2:C101)-COUNT(Clean!C2:C101) -> 0 | D5: AVERAGE skips text without warning
A6: Average height (cm) | B6: =AVERAGE(Messy!C2:C109) -> 173.5102 | C6: =AVERAGE(Clean!C2:C101) -> 167.85567 | D6: Metres and typos wreck the messy average
A7: Average sleep (hours) | B7: =AVERAGE(Messy!D2:D109) -> 7.1634615 | C7: =AVERAGE(Clean!D2:D101) -> 7.0909091 | D7: Text and one impossible 25 skew it
A8: Count of exactly 'Yes' for breakfast | B8: =COUNTIF(Messy!E2:E109,"Yes") -> 36 | C8: =COUNTIF(Clean!E2:E101,"Yes") -> 68 | D8: Misses Y, 'Yes ' and Yess
A9: Share eating breakfast | B9: =COUNTIF(Messy!E2:E109,"Yes")/COUNTA(Messy!E2:E109) -> 0.33333333 | C9: =COUNTIF(Clean!E2:E101,"Yes")/COUNTA(Clean!E2:E101) -> 0.68 | D9: Undercounted and double-counted at once
A10: Different labels for travel to school | B10: =SUMPRODUCT(1/COUNTIF(Messy!F2:F109,Messy!F2:F109)) -> 11 | C10: =SUMPRODUCT(1/COUNTIF(Clean!F2:F101,Clean!F2:F101)) -> 4 | D10: 11 labels for 4 ideas
A12: Reminder: if you can't tell what a value should be, leave it blank and say so. Never guess silently.
